Workbook

Sheet Expenses
A1: Year | B1: Month | C1: ID | D1: Date | E1: Category | F1: Description | G1: Amount | H1: Paid? | I1: Mode | J1: Payment Date | K1: Rating | L1: Vendor Category | M1: Remarks
C2: 47 | D2: 45722 | E2: LOCAL PURCHASE | F2: Temprature controller | G2: 2710 | H2: TRUE | I2: Cash | K2: 5
C3: 228 | D3: 45736 | E3: MARKETING | F3: FOOD HUNTER SABU | G3: 25000 | H3: TRUE | I3: Cash | K3: 5
C4: 143 | D4: 45738 | E4: GREENZ VEGGIES | F4: veggies | G4: 2253 | H4: TRUE | I4: UPI | K4: 5
C5: 50 | D5: 45739 | E5: T3 SPECIALITY | F5: prawns | G5: 1160 | H5: TRUE | I5: Bank | K5: 5
C6: 51 | D6: 45741 | E6: TRIO MEATS KTM | F6: Oregano | G6: 1826 | H6: TRUE | I6: Bank | K6: 5
C7: 64 | D7: 45741 | E7: MATHA MEATS | F7: pork ribs | G7: 1805 | H7: TRUE | I7: Bank | K7: 5
C8: 144 | D8: 45741 | E8: Greenz Veggies | F8: veggies | G8: 558 | H8: TRUE | I8: UPI | K8: 5
C9: 53 | D9: 45742 | E9: MATHA MEATS | F9: Beef | G9: 720 | H9: TRUE | I9: Bank | K9: 5
C10: 145 | D10: 45742 | E10: Greenz Veggies | F10: veggies | G10: 1529 | H10: TRUE | I10: UPI | K10: 5
C11: 146 | D11: 45742 | E11: Greenz Veggies | F11: veggies | G11: 85 | H11: TRUE | I11: UPI | K11: 5
C12: 334 | D12: 45742 | E12: PULI WOOD CHINGAVANAM | F12: PULI WOOD CHINGAVANAM | G12: 19740 | H12: TRUE | I12: UPI | K12: 0
C13: 708 | D13: 45742 | E13: TEL PHONE | F13: AIRTEL PHILOS KAKKANAD | G13: 250 | H13: TRUE | I13: UPI | K13: 0
... C31: 148 | D31: 45748 | E31: Greenz Veggies | F31: veggies | G31: 2135 | H31: TRUE | I31: UPI | K31: 5
C32: 254 | D32: 45748 | E32: LULU KOCHI | F32: salmon /avocado | G32: 2807 | H32: TRUE | I32: UPI
C33: 63 | D33: 45749 | E33: MATHA MEATS | F33: BEEF | G33: 2180 | H33: TRUE | I33: Bank | K33: 5
C34: 65 | D34: 45750 | E34: UNITED TRADERS KTM | F34: wheet flour | G34: 2943 | H34: TRUE | I34: UPI | K34: 5
C35: 66 | D35: 45750 | E35: LOCAL PURCHASE | F35: floor brush | G35: 1307 | H35: TRUE | I35: Cash | K35: 5
C36: 8 | D36: 45751 | E36: ARACKAL BHARATH GAS | F36: GAS | G36: 1720 | H36: TRUE | I36: Bank | K36: 5
C37: 67 | D37: 45751 | E37: T3 SPECIALITY | F37: strawbery fruity | G37: 3409 | H37: TRUE | I37: Bank | K37: 5
C38: 68 | D38: 45752 | E38: POLAR ICE CUBES | F38: ice cube | G38: 350 | H38: TRUE | I38: UPI | K38: 5
C39: 69 | D39: 45752 | E39: MATHA MEATS | F39: Chicken | G39: 2238 | H39: TRUE | I39: Bank | K39: 5
C40: 70 | D40: 45752 | E40: T3 SPECIALITY | F40: CHEESE | G40: 5880 | H40: TRUE | I40: Bank | K40: 5
C41: 71 | D41: 45752 | E41: T3 SPECIALITY | F41: CHEESE | G41: 3506 | H41: TRUE | I41: Bank | K41: 5
C42: 72 | D42: 45752 | E42: LOCAL PURCHASE | F42: soda | G42: 600 | H42: TRUE | I42: Bank | K42: 5
C43: 225 | D43: 45752 | E43: STAFF SALARY | F43: SALARY MARCH (10 DAYS) | G43: 48000 | H43: TRUE | I43: Bank | K43: 5
C44: 255 | D44: 45752 | E44: LULU KOCHI | F44: salmon /avocado | G44: 2345 | H44: TRUE | I44: UPI
C45: 73 | D45: 45754 | E45: GROW GREENS | F45: Sunflower | G45: 300 | H45: TRUE | I45: UPI | K45: 5
C46: 74 | D46: 45754 | E46: T3 SPECIALITY | F46: peperoni | G46: 8439 | H46: TRUE | I46: Bank | K46: 5
C47: 147 | D47: 45754 | E47: Greenz Veggies | F47: veggies | G47: 1718.5 | H47: TRUE | I47: UPI | K47: 5
C48: 75 | D48: 45755 | E48: T3 SPECIALITY | F48: bufflo cut | G48: 2828 | H48: TRUE | I48: Bank | K48: 5
C49: 76 | D49: 45755 | E49: MATHA MEATS | F49: pork ribs | G49: 4734 | H49: TRUE | I49: Bank | K49: 5
C50: 77 | D50: 45755 | E50: POLAR ICE CUBES | F50: ice cube | G50: 140 | H50: TRUE | I50: UPI | K50: 5
C51: 78 | D51: 45756 | E51: KSEB | F51: kseb | G51: 7802 | H51: TRUE | I51: UPI | K51: 5
C52: 79 | D52: 45756 | E52: WATER SUPPLY | F52: 2000L | G52: 800 | H52: TRUE | I52: UPI | K52: 5
C53: 80 | D53: 45756 | E53: LERA COCA COLA | F53: sprite | G53: 3290 | H53: TRUE | I53: Bank | K53: 5
C54: 81 | D54: 45756 | E54: T3 SPECIALITY | F54: fruty mango | G54: 3156 | H54: TRUE | I54: Bank | K54: 5
C55: 152 | D55: 45756 | E55: Greenz Veggies | F55: veggies | G55: 676 | H55: TRUE | I55: Bank | K55: 5
C56: 12 | D56: 45757 | E56: ARACKAL BHARATH GAS | F56: GAS | G56: 1720 | H56: TRUE | I56: UPI | K56: 5
... C68: 153 | D68: 45759 | E68: Greenz Veggies | F68: veggies | G68: 1112.25 | H68: TRUE | I68: Bank | K68: 5
...

Sheet Pivot Table 7

Sheet Daybook
A1: Month | B1: Date | C1: Week | D1: Description | E1: Income | F1: Expense
A2: 04-Apr | B2: 45773 | C2: 17 | D2: Matha meats | F2: 2997
A3: 04-Apr | B3: 45775 | C3: 18 | D3: Grow greens | F3: 300
A4: 04-Apr | B4: 45775 | C4: 18 | D4: Right solution Tissue paper | F4: 1320
A5: 04-Apr | B5: 45774 | C5: 18 | D5: Matha meats | F5: 2880
A6: 04-Apr | B6: 45774 | C6: 18 | D6: Polar Ice Cubes | F6: 300
A7: 04-Apr | B7: 45775 | C7: 18 | D7: Polar Ice Cubes | F7: 75
A8: 04-Apr | B8: 45748 | C8: 14 | D8: Local purchase | F8: 156
A9: 04-Apr | B9: 45751 | C9: 14 | D9: Arackal bharath gas | F9: 1720
A10: 04-Apr | B10: 45770 | C10: 17 | D10: Arackal bharath gas | F10: 1760
A11: 04-Apr | B11: 45762 | C11: 16 | D11: Arackal bharath gas | F11: 1720
A12: 04-Apr | B12: 45760 | C12: 16 | D12: Arackal bharath gas | F12: 5280
A13: 04-Apr | B13: 45757 | C13: 15 | D13: Arackal bharath gas | F13: 1720
... A319: 06-Jun | B319: 45829 | C319: 25 | D319: T3 Speciality | F319: 5880
A320: 06-Jun | B320: 45831 | C320: 26 | D320: Trio meats Kottayam
A321: 06-Jun | B321: 45833 | C321: 26 | D321: Arackal bharath gas | F321: 1740
A322: 06-Jun | B322: 45833 | C322: 26 | D322: EURO INDIA KOCHI | F322: 4435
A323: 05-May | B323: 45787 | C323: 19 | D323: EURO INDIA KOCHI | F323: 2262
A324: 06-Jun | B324: 45829 | C324: 25 | D324: EURO INDIA KOCHI | F324: 4435
A325: 05-May | B325: 45799 | C325: 21 | D325: EURO INDIA KOCHI | F325: 4435
A326: 04-Apr | B326: 45768 | C326: 17 | D326: Diamond | F326: 1370
A327: 06-Jun | B327: 45833 | C327: 26 | D327: Diamond | F327: 1217
A328: 06-Jun | B328: 45826 | C328: 25 | D328: Greenz Veggies | F328: 731
A329: 06-Jun | B329: 45832 | C329: 26 | D329: Greenz Veggies | F329: 95
A330: 06-Jun | B330: 45832 | C330: 26 | D330: Greenz Veggies | F330: 813
A331: 06-Jun | B331: 45826 | C331: 25 | D331: Greenz Veggies | F331: 836
A332: 06-Jun | B332: 45824 | C332: 25 | D332: Greenz Veggies | F332: 1160
... A420: 07-Jul | B420: 45854 | C420: 29 | D420: T3 Speciality | F420: 6986
A421: 04-Apr | B421: 45749 | C421: 14 | D421: Kakkanad Income | E421: 10655
A422: 04-Apr | B422: 45750 | C422: 14 | D422: Kakkanad Income | E422: 15640
A423: 04-Apr | B423: 45751 | C423: 14 | D423: Kakkanad Income | E423: 18210
A424: 04-Apr | B424: 45752 | C424: 14 | D424: Kakkanad Income | E424: 10385
A425: 04-Apr | B425: 45753 | C425: 15 | D425: Kakkanad Income | E425: 16845
A426: 04-Apr | B426: 45754 | C426: 15 | D426: Kakkanad Income | E426: 20030
A427: 04-Apr | B427: 45755 | C427: 15 | D427: Kakkanad Income | E427: 16870
A428: 04-Apr | B428: 45756 | C428: 15 | D428: Kakkanad Income | E428: 2635
A429: 04-Apr | B429: 45757 | C429: 15 | D429: Kakkanad Income | E429: 24368
A430: 04-Apr | B430: 45758 | C430: 15 | D430: Kakkanad Income | E430: 27640
A431: 04-Apr | B431: 45759 | C431: 15 | D431: Kakkanad Income | E431: 23040
A432: 04-Apr | B432: 45760 | C432: 16 | D432: Kakkanad Income | E432: 19155
...

Sheet SwiggyInvoiceSummary
A1: Philos Kakkanad Swiggy Trasaction Tracker
Y2: Actual Payment (from Swiggy Stmnt) | Z2: Difference | AA2: Swiggy % | AB2: Philos % | AD2: =A2 -> PaymentID | AE2: =B2 -> No. of Ord. | AF2: =F2 -> [A] Net Bill Value | AG2: [B] Swiggy Fee | AH2: [C] Cancellation | AI2: [D] Taxes | AJ2: =X2 -> Net Payout [A-B-C-D] | AK2: Actual Pay | AL2: Difference | AM2: Swiggy % | AN2: Philos %
Y3: 4386.32 | Z3: =X3-Y3 -> 1179 | AA3: =(R3+S3+T3+Z3)/F3 -> 0.32882506 | AB3: =Y3/F3 -> 0.67017876 | AD3: =A3 -> 45763 | AE3: =B3 -> 7 | AF3: =F3 -> 6545 | AG3: =R3 -> 973.16 | AH3: =S3+T3 -> 0 | AI3: =U3+V3+W3 -> 333.8 | AJ3: =X3 -> 5565.32 | AK3: =Y3 -> 4386.32 | AL3: =Z3 -> 1179 | AM3: =AA3 -> 0.32882506 | AN3: =AB3 -> 0.67017876
Y4: 11190.28 | Z4: =X4-Y4 -> 0.01 | AA4: =(R4+S4+T4+Z4)/F4 -> 0.1486815 | AB4: =Y4/F4 -> 0.85032458 | AD4: =A4 -> 45770 | AE4: =B4 -> 16 | AF4: =F4 -> 13160.01 | AG4: =R4 -> 1956.64 | AH4: =S4+T4 -> 0 | AI4: =U4+V4+W4 -> 671.16 | AJ4: =X4 -> 11190.29 | AK4: =Y4 -> 11190.28 | AL4: =Z4 -> 0.01 | AM4: =AA4 -> 0.1486815 | AN4: =AB4 -> 0.85032458
Y5: 39721.55 | Z5: =X5-Y5 -> 0 | AA5: =(R5+S5+T5+Z5)/F5 -> 0.15439719 | AB5: =Y5/F5 -> 0.84460026 | AD5: =A5 -> 45777 | AE5: =B5 -> 53 | AF5: =F5 -> 47030 | AG5: =R5 -> 6992.3 | AH5: =S5+T5 -> 269 | AI5: =U5+V5+W5 -> 2398.52 | AJ5: =X5 -> 39721.55 | AK5: =Y5 -> 39721.55 | AL5: =Z5 -> 0 | AM5: =AA5 -> 0.15439719 | AN5: =AB5 -> 0.84460026
Y6: 15152.76 | Z6: =X6-Y6 -> 0 | AA6: =(R6+S6+T6+Z6)/F6 -> 0.14867677 | AB6: =Y6/F6 -> 0.85032323 | AD6: =A6 -> 45782 | AE6: =B6 -> 18 | AF6: =F6 -> 17820 | AG6: =R6 -> 2649.42 | AH6: =S6+T6 -> 0 | AI6: =U6+V6+W6 -> 908.82 | AJ6: =X6 -> 15152.76 | AK6: =Y6 -> 15152.76 | AL6: =Z6 -> 0 | AM6: =AA6 -> 0.14867677 | AN6: =AB6 -> 0.85032323
Y7: 10486.25 | Z7: =X7-Y7 -> 0 | AA7: =(R7+S7+T7+Z7)/F7 -> 0.2017447 | AB7: =Y7/F7 -> 0.79725097 | AD7: =A7 -> 45784 | AE7: =B7 -> 15 | AF7: =F7 -> 13153.01 | AG7: =R7 -> 1955.55 | AH7: =S7+T7 -> 698 | AI7: =U7+V7+W7 -> 670.81 | AJ7: =X7 -> 10486.25 | AK7: =Y7 -> 10486.25 | AL7: =Z7 -> 0 | AM7: =AA7 -> 0.2017447 | AN7: =AB7 -> 0.79725097
Y8: 14375.22 | Z8: =X8-Y8 -> 3.01 | AA8: =(R8+S8+T8+Z8)/F8 -> 0.1492814 | AB8: =Y8/F8 -> 0.84972082 | AD8: =A8 -> 45791 | AE8: =B8 -> 24 | AF8: =F8 -> 16917.58 | AG8: =R8 -> 2522.47 | AH8: =S8+T8 -> 0 | AI8: =U8+V8+W8 -> 862.81 | AJ8: =X8 -> 14378.23 | AK8: =Y8 -> 14375.22 | AL8: =Z8 -> 3.01 | AM8: =AA8 -> 0.1492814 | AN8: =AB8 -> 0.84972082
Y9: 15528.99 | Z9: =X9-Y9 -> -0.03 | AA9: =(R9+S9+T9+Z9)/F9 -> 0.17850084 | AB9: =Y9/F9 -> 0.8224212 | AD9: =A9 -> 45798 | AE9: =B9 -> 24 | AF9: =F9 -> 18882.04 | AG9: =R9 -> 2633.39 | AH9: =S9+T9 -> 737.1 | AI9: =U9+V9+W9 -> 926.71 | AJ9: =X9 -> 15528.96 | AK9: =Y9 -> 15528.99 | AL9: =Z9 -> -0.03 | AM9: =AA9 -> 0.17850084 | AN9: =AB9 -> 0.8224212
Y10: 16561.62 | Z10: =X10-Y10 -> 0.01 | AA10: =(R10+S10+T10+Z10)/F10 -> 0.15479356 | AB10: =Y10/F10 -> 0.84420532 | AD10: =A10 -> 45805 | AE10: =B10 -> 29 | AF10: =F10 -> 19618 | AG10: =R10 -> 2916.73 | AH10: =S10+T10 -> 120 | AI10: =U10+V10+W10 -> 1000.47 | AJ10: =X10 -> 16561.63 | AK10: =Y10 -> 16561.62 | AL10: =Z10 -> 0.01 | AM10: =AA10 -> 0.15479356 | AN10: =AB10 -> 0.84420532
Y11: 24755.42 | Z11: =X11-Y11 -> -0.01 | AA11: =(R11+S11+T11+Z11)/F11 -> 0.14868056 | AB11: =Y11/F11 -> 0.85032127 | AD11: =A11 -> 45812 | AE11: =B11 -> 34 | AF11: =F11 -> 29113.02 | AG11: =R11 -> 4328.55 | AH11: =S11+T11 -> 0 | AI11: =U11+V11+W11 -> 1484.76 | AJ11: =X11 -> 24755.41 | AK11: =Y11 -> 24755.42 | AL11: =Z11 -> -0.01 | AM11: =AA11 -> 0.14868056 | AN11: =AB11 -> 0.85032127
Y12: 25440.8 | Z12: =X12-Y12 -> 3539.98 | AA12: =(R12+S12+T12+Z12)/F12 -> 0.25254546 | AB12: =Y12/F12 -> 0.74645197 | AD12: =A12 -> 45819 | AE12: =B12 -> 42 | AF12: =F12 -> 34082.3 | AG12: =R12 -> 5067.35 | AH12: =S12+T12 -> 0 | AI12: =U12+V12+W12 -> 1738.28 | AJ12: =X12 -> 28980.78 | AK12: =Y12 -> 25440.8 | AL12: =Z12 -> 3539.98 | AM12: =AA12 -> 0.25254546 | AN12: =AB12 -> 0.74645197
Y13: 24872.2 | Z13: =X13-Y13 -> 3539.99 | AA13: =(R13+S13+T13+Z13)/F13 -> 0.25462574 | AB13: =Y13/F13 -> 0.74437466 | AD13: =A13 -> 45826 | AE13: =B13 -> 42 | AF13: =F13 -> 33413.55 | AG13: =R13 -> 4967.96 | AH13: =S13+T13 -> 0 | AI13: =U13+V13+W13 -> 1704.14 | AJ13: =X13 -> 28412.19 | AK13: =Y13 -> 24872.2 | AL13: =Z13 -> 3539.99 | AM13: =AA13 -> 0.25462574 | AN13: =AB13 -> 0.74437466
Y14: 24947.72 | Z14: =X14-Y14 -> 3540.03 | AA14: =(R14+S14+T14+Z14)/F14 -> 0.2543452 | AB14: =Y14/F14 -> 0.74465338 | AD14: =A14 -> 45833 | AE14: =B14 -> 34 | AF14: =F14 -> 33502.46 | AG14: =R14 -> 4981.16 | AH14: =S14+T14 -> 0 | AI14: =U14+V14+W14 -> 1708.65 | AJ14: =X14 -> 28487.75 | AK14: =Y14 -> 24947.72 | AL14: =Z14 -> 3540.03 | AM14: =AA14 -> 0.2543452 | AN14: =AB14 -> 0.74465338
... Y17: 41700 | Z17: =X17-Y17 -> 0.02 | AA17: =(R17+S17+T17+Z17)/F17 -> 0.15923133 | AB17: =Y17/F17 -> 0.83977141 | AD17: =A17 -> 45854 | AE17: =B17 -> 50 | AF17: =F17 -> 49656.37 | AG17: =R17 -> 7382.83 | AH17: =S17+T17 -> 524 | AI17: =U17+V17+W17 -> 2532.36 | AJ17: =X17 -> 41700.02 | AK17: =Y17 -> 41700 | AL17: =Z17 -> 0.02 | AM17: =AA17 -> 0.15923133 | AN17: =AB17 -> 0.83977141
Y18: =SUM(Y5:Y17) -> 330132.41 | Z18: =SUM(Z5:Z17) -> 15376.92 | AA18: =AVERAGE(AA6:AA17) -> 0.19107856 | AB18: =AVERAGE(AB6:AB17) -> 0.80808067 | AE18: =B18 -> 483 | AF18: =SUM(AF5:AF17) -> 408851.2 | AG18: =SUM(AG5:AG17) -> 60620.69 | AH18: =SUM(AH5:AH17) -> 2348.1 | AI18: =SUM(AI5:AI17) -> 20815.15 | AJ18: =SUM(AJ5:AJ17) -> 345509.33 | AK18: =SUM(AK5:AK17) -> 330132.41 | AL18: =SUM(AL5:AL17) -> 15376.92 | AM18: =AVERAGE(AM5:AM17) -> 0.18825692 | AN18: =AVERAGE(AN5:AN17) -> 0.81088987
D19: AOV
C20: =A3 -> 45763 | D20: =F3/B3 -> 935
C21: =A4 -> 45770 | D21: =F4/B4 -> 822.50063
C22: =A5 -> 45777 | D22: =F5/B5 -> 887.35849
C23: =A6 -> 45782 | D23: =F6/B6 -> 990
C24: =A7 -> 45784 | D24: =F7/B7 -> 876.86733
C25: =A8 -> 45791 | D25: =F8/B8 -> 704.89917
C26: =A9 -> 45798 | D26: =F9/B9 -> 786.75167
C27: =A10 -> 45805 | D27: =F10/B10 -> 676.48276
C28: =A11 -> 45812 | D28: =F11/B11 -> 856.26529
C29: =A12 -> 45819 | D29: =F12/B12 -> 811.48333
C30: =A13 -> 45826 | D30: =F13/B13 -> 795.56071
C31: =A14 -> 45833 | D31: =F14/B14 -> 985.36647
... C33: =A16 -> 45847 | D33: =F16/B16 -> 975.00026

Sheet Menu
A1: Name | B1: Online_Name | C1: Description | D1: Short_Code | E1: Short_Code_2 | F1: Sap_Code | G1: HSN_Code | H1: Parent_Category | I1: Category | J1: Category_online_display | K1: Price | L1: Attributes | M1: Goods_Services | N1: Unit | O1: is_Self_Item_Recipe | P1: minimum_stock_level | Q1: at_par_stock_level | R1: Rank | S1: Packing_Charges | T1: Allow_Decimal_Qty | U1: Addon_Group_Name | V1: Addon_Group_Selection | W1: Addon_Group_Min | X1: Addon_Group_Max | Y1: Variation_group_name | Z1: Variation | AA1: Variation_Price | AB1: Variation_Sap_Code | AC1: Variation_Packing_Charges | AD1: Variation 2 | AE1: Variation_Price 2 | AF1: Variation_Sap_Code 2 | AG1: Variation_Packing_Charges 2 | AH1: Variation 3 | AI1: Variation_Price 3 | AJ1: Variation_Sap_Code 3 | AK1: Variation_Packing_Charges 3
A2: Cajun Fried Prawns | B2: Cajun Fried Prawns | D2: 1 | I2: Western | K2: 380 | L2: non-veg | O2: 0 | R2: 1 | S2: 0 | T2: Yes
A3: Moroccan Meat Balls | B3: Moroccan Meat Balls | D3: 2 | I3: Western | K3: 360 | L3: non-veg | O3: 0 | R3: 1 | S3: 0 | T3: Yes
A4: Jamaican Chicken Skewer | B4: Jamaican Chicken Skewer | D4: 3 | I4: Western | K4: 310 | L4: non-veg | O4: 0 | R4: 1 | S4: 0 | T4: Yes
A5: Spicy Corn & Cheese Balls | B5: Spicy Corn & Cheese Balls | D5: 4 | I5: Western | K5: 310 | L5: veg | O5: 0 | R5: 1 | S5: 0 | T5: Yes
A6: Nachos With Confit Tomato Salsa | B6: Nachos With Confit Tomato Salsa | D6: 5 | I6: Western | K6: 260 | L6: veg | O6: 0 | R6: 1 | S6: 0 | T6: Yes
A7: Pasta Arabiata | B7: Pasta Arabiata | D7: 6 | I7: Pastas | K7: 340 | L7: veg | O7: 0 | R7: 1 | S7: 0 | T7: Yes
A8: Classic Pasta | B8: Classic Pasta | D8: 8 | I8: Pastas | K8: 470 | L8: non-veg | O8: 0 | R8: 1 | S8: 0 | T8: Yes
A9: Mexican Tostadas | B9: Mexican Tostadas | D9: 9 | I9: Wraps/Burger | K9: 380 | L9: veg | O9: 0 | R9: 1 | S9: 0 | T9: Yes
A10: Chicken Quesadilla | B10: Chicken Quesadilla | D10: 10 | I10: Wraps/Burger | K10: 420 | L10: non-veg | O10: 0 | R10: 1 | S10: 0 | T10: Yes
A11: Stuffed Chicken Roulade | B11: Stuffed Chicken Roulade | D11: stuffed chicken roul | I11: Mains | K11: 490 | L11: non-veg | O11: 0 | R11: 1 | S11: 0 | T11: Yes
A12: Grilled Beef Tenderloin | B12: Grilled Beef Tenderloin | D12: grilled beef tenderl | I12: Mains | K12: 520 | L12: non-veg | O12: 0 | R12: 1 | S12: 0 | T12: Yes
A13: Asian Bbq Pork Ribs | B13: Asian Bbq Pork Ribs | D13: 14 | I13: Asian | K13: 380 | L13: non-veg | O13: 0 | R13: 1 | S13: 0 | T13: Yes
A14: Shepherds Pie | B14: Shepherds Pie | D14: shepherds pie | I14: Mains | K14: 520 | L14: non-veg | O14: 0 | R14: 1 | S14: 0 | T14: Yes
A15: Korean Pork Rice | B15: Korean Pork Rice | D15: korean pork rice | I15: Mains | K15: 490 | L15: non-veg | O15: 0 | R15: 1 | S15: 0 | T15: Yes
A16: Loaded Fries | B16: Loaded Fries | D16: 17 | I16: Sides | K16: 220 | L16: veg | O16: 0 | R16: 1 | S16: 0 | T16: Yes
A17: Chilly Cheese Toast | B17: Chilly Cheese Toast | D17: 18 | I17: Sides | K17: 210 | L17: veg | O17: 0 | R17: 1 | S17: 0 | T17: Yes
A18: Potato Wedges | B18: Potato Wedges | D18: 19 | I18: Sides | K18: 180 | L18: veg | O18: 0 | R18: 1 | S18: 0 | T18: Yes
A19: French Fries | B19: French Fries | D19: 20 | I19: Sides | K19: 160 | L19: veg | O19: 0 | R19: 1 | S19: 0 | T19: Yes
A20: Garlic Bread | B20: Garlic Bread | D20: 21 | I20: Sides | K20: 120 | L20: veg | O20: 0 | R20: 1 | S20: 0 | T20: Yes
A21: Prawn Tempura | B21: Prawn Tempura | D21: 22 | I21: Asian | K21: 380 | L21: non-veg | O21: 0 | R21: 1 | S21: 0 | T21: Yes
A22: Thai Chicken Satay | B22: Thai Chicken Satay | D22: thai chicken satay | I22: Asian | K22: 360 | L22: non-veg | O22: 0 | R22: 1 | S22: 0 | T22: Yes
A23: Chicken Karaage | B23: Chicken Karaage | D23: 24 | I23: Asian | K23: 360 | L23: non-veg | O23: 0 | R23: 1 | S23: 0 | T23: Yes
A24: Teriyaki Sliced Beef Tenderloin | B24: Teriyaki Sliced Beef Tenderloin | D24: 25 | I24: Asian | K24: 360 | L24: non-veg | O24: 0 | R24: 1 | S24: 0 | T24: Yes
A25: Thai Paneer Satay | B25: Thai Paneer Satay | D25: 26 | I25: Asian | K25: 310 | L25: veg | O25: 0 | R25: 1 | S25: 0 | T25: Yes
A26: Pork Tonkotsu Ramen | B26: Pork Tonkotsu Ramen | D26: 27 | I26: Ramen Bowls | K26: 450 | L26: non-veg | O26: 0 | R26: 1 | S26: 0 | T26: Yes
A27: Korean Pulled Chicken Ramen | B27: Korean Pulled Chicken Ramen | D27: 28 | I27: Ramen Bowls | K27: 420 | L27: non-veg | O27: 0 | R27: 1 | S27: 0 | T27: Yes
A28: Classic Maki | B28: Classic Maki | D28: 29 | I28: Authentic Japanese Sushi | K28: 490 | L28: veg | O28: 0 | R28: 1 | S28: 0 | T28: Yes
A29: Salmon Tartar Maki | B29: Salmon Tartar Maki | D29: 30 | I29: Authentic Japanese Sushi | K29: 650 | L29: non-veg | O29: 0 | R29: 1 | S29: 0 | T29: Yes
A30: Spicy Crunchy Tuna Roll | B30: Spicy Crunchy Tuna Roll | D30: 31 | I30: Authentic Japanese Sushi | K30: 650 | L30: non-veg | O30: 0 | R30: 1 | S30: 0 | T30: Yes
A31: Crispy Salmon Tempura Roll | B31: Crispy Salmon Tempura Roll | D31: 32 | I31: Authentic Japanese Sushi | K31: 650 | L31: non-veg | O31: 0 | R31: 1 | S31: 0 | T31: Yes
A32: Classic California Roll | B32: Classic California Roll | D32: 33 | I32: Authentic Japanese Sushi | K32: 700 | L32: non-veg | O32: 0 | R32: 1 | S32: 0 | T32: Yes
A33: Tuna Akami Roll | B33: Tuna Akami Roll | D33: 34 | I33: Authentic Japanese Sushi | K33: 650 | L33: non-veg | O33: 0 | R33: 1 | S33: 0 | T33: Yes
A34: Futo Maki | B34: Futo Maki | D34: 35 | I34: Authentic Japanese Sushi | K34: 700 | L34: veg | O34: 0 | R34: 1 | S34: 0 | T34: Yes
A35: Crunchy Caprese Roll | B35: Crunchy Caprese Roll | D35: 36 | I35: Authentic Japanese Sushi | K35: 450 | L35: veg | O35: 0 | R35: 1 | S35: 0 | T35: Yes
A36: Wild Mushroom | B36: Wild Mushroom | D36: 37 | I36: Veg Pizzas | K36: 0 | L36: veg | O36: 0 | R36: 1 | S36: 0 | T36: Yes | Y36: Quantity | Z36: 8 Inch | AA36: 375 | AC36: 0 | AD36: 10 Inch | AE36: 525 | AG36: 0 | AH36: 12 Inch | AI36: 650 | AK36: 0
A37: Melanzane | B37: Melanzane | D37: 38 | I37: Veg Pizzas | K37: 0 | L37: veg | O37: 0 | R37: 1 | S37: 0 | T37: Yes | Y37: Quantity | Z37: 8 Inch | AA37: 350 | AC37: 0 | AD37: 10 Inch | AE37: 450 | AG37: 0 | AH37: 12 Inch | AI37: 550 | AK37: 0
A38: Premavera | B38: Premavera | D38: 39 | I38: Veg Pizzas | K38: 0 | L38: veg | O38: 0 | R38: 1 | S38: 0 | T38: Yes | Y38: Quantity | Z38: 8 Inch | AA38: 375 | AC38: 0 | AD38: 10 Inch | AE38: 525 | AG38: 0 | AH38: 12 Inch | AI38: 650 | AK38: 0
A39: Grilled Paneer | B39: Grilled Paneer | D39: 40 | I39: Veg Pizzas | K39: 0 | L39: veg | O39: 0 | R39: 1 | S39: 0 | T39: Yes | Y39: Quantity | Z39: 8 Inch | AA39: 375 | AC39: 0 | AD39: 10 Inch | AE39: 525 | AG39: 0 | AH39: 12 Inch | AI39: 650 | AK39: 0
A40: Margherita | B40: Margherita | D40: 41 | I40: Veg Pizzas | K40: 0 | L40: veg | O40: 0 | R40: 1 | S40: 0 | T40: Yes | Y40: Quantity | Z40: 8 Inch | AA40: 325 | AC40: 0 | AD40: 10 Inch | AE40: 450 | AG40: 0 | AH40: 12 Inch | AI40: 600 | AK40: 0
...

Sheet Income
A1: Sl | B1: Month | C1: Date | D1: Day | E1: Week Number | F1: Petpooja Actual | G1: GST 5% | H1: Petpooja | I1: Swiggy | J1: Swiggy Payout | K1: Paper Bill | L1: Zomato | M1: Zomato Payout | N1: Total | P1: FED BANK | Q1: YES BANK | R1: SWIGGY | S1: SWIGGY1 | T1: Cash | U1: Alerts
A2: 1 | B2: =TEXT(C2,"MM")&"-"&text(C2,"MMM") -> 04-Apr | C2: 45749 | D2: =text(C2,"ddd") -> Wed | E2: =WEEKNUM(C2,1) -> 14 | F2: 0 | G2: =if(F2<>"",F2*0.05,"") -> 0 | H2: =F2-G2 -> 0 | I2: 0 | K2: 10655 | N2: =if(or(H2<>"",I2<>"",K2<>""),sum(H2:K2),"") -> 10655
A3: 2 | B3: =TEXT(C3,"MM")&"-"&text(C3,"MMM") -> 04-Apr | C3: 45750 | D3: =text(C3,"ddd") -> Thu | E3: =WEEKNUM(C3,1) -> 14 | F3: 0 | G3: =if(F3<>"",F3*0.05,"") -> 0 | H3: =F3-G3 -> 0 | I3: 0 | K3: 15640 | N3: =if(or(H3<>"",I3<>"",K3<>""),sum(H3:K3),"") -> 15640
A4: 3 | B4: =TEXT(C4,"MM")&"-"&text(C4,"MMM") -> 04-Apr | C4: 45751 | D4: =text(C4,"ddd") -> Fri | E4: =WEEKNUM(C4,1) -> 14 | F4: 0 | G4: =if(F4<>"",F4*0.05,"") -> 0 | H4: =F4-G4 -> 0 | I4: 0 | K4: 18210 | N4: =if(or(H4<>"",I4<>"",K4<>""),sum(H4:K4),"") -> 18210
A5: 4 | B5: =TEXT(C5,"MM")&"-"&text(C5,"MMM") -> 04-Apr | C5: 45752 | D5: =text(C5,"ddd") -> Sat | E5: =WEEKNUM(C5,1) -> 14 | F5: 0 | G5: =if(F5<>"",F5*0.05,"") -> 0 | H5: =F5-G5 -> 0 | I5: 0 | K5: 10385 | N5: =if(or(H5<>"",I5<>"",K5<>""),sum(H5:K5),"") -> 10385
A6: 5 | B6: =TEXT(C6,"MM")&"-"&text(C6,"MMM") -> 04-Apr | C6: 45753 | D6: =text(C6,"ddd") -> Sun | E6: =WEEKNUM(C6,1) -> 15 | F6: 0 | G6: =if(F6<>"",F6*0.05,"") -> 0 | H6: =F6-G6 -> 0 | I6: 0 | K6: 16845 | N6: =if(or(H6<>"",I6<>"",K6<>""),sum(H6:K6),"") -> 16845
A7: 6 | B7: =TEXT(C7,"MM")&"-"&text(C7,"MMM") -> 04-Apr | C7: 45754 | D7: =text(C7,"ddd") -> Mon | E7: =WEEKNUM(C7,1) -> 15 | F7: 20030 | G7: =if(F7<>"",F7*0.05,"") -> 1001.5 | H7: =F7-G7 -> 19028.5 | I7: 0 | K7: 0 | N7: =if(or(H7<>"",I7<>"",K7<>""),sum(H7:K7),"") -> 19028.5
A8: 7 | B8: =TEXT(C8,"MM")&"-"&text(C8,"MMM") -> 04-Apr | C8: 45755 | D8: =text(C8,"ddd") -> Tue | E8: =WEEKNUM(C8,1) -> 15 | F8: 16870 | G8: =if(F8<>"",F8*0.05,"") -> 843.5 | H8: =F8-G8 -> 16026.5 | I8: 0 | K8: 0 | N8: =if(or(H8<>"",I8<>"",K8<>""),sum(H8:K8),"") -> 16026.5
A9: 8 | B9: =TEXT(C9,"MM")&"-"&text(C9,"MMM") -> 04-Apr | C9: 45756 | D9: =text(C9,"ddd") -> Wed | E9: =WEEKNUM(C9,1) -> 15 | F9: 2635 | G9: =if(F9<>"",F9*0.05,"") -> 131.75 | H9: =F9-G9 -> 2503.25 | I9: 0 | K9: 0 | N9: =if(or(H9<>"",I9<>"",K9<>""),sum(H9:K9),"") -> 2503.25
A10: 9 | B10: =TEXT(C10,"MM")&"-"&text(C10,"MMM") -> 04-Apr | C10: 45757 | D10: =text(C10,"ddd") -> Thu | E10: =WEEKNUM(C10,1) -> 15 | F10: 24368 | G10: =if(F10<>"",F10*0.05,"") -> 1218.4 | H10: =F10-G10 -> 23149.6 | I10: 0 | K10: 0 | N10: =if(or(H10<>"",I10<>"",K10<>""),sum(H10:K10),"") -> 23149.6
A11: 10 | B11: =TEXT(C11,"MM")&"-"&text(C11,"MMM") -> 04-Apr | C11: 45758 | D11: =text(C11,"ddd") -> Fri | E11: =WEEKNUM(C11,1) -> 15 | F11: 27640 | G11: =if(F11<>"",F11*0.05,"") -> 1382 | H11: =F11-G11 -> 26258 | I11: 0 | K11: 0 | N11: =if(or(H11<>"",I11<>"",K11<>""),sum(H11:K11),"") -> 26258
A12: 11 | B12: =TEXT(C12,"MM")&"-"&text(C12,"MMM") -> 04-Apr | C12: 45759 | D12: =text(C12,"ddd") -> Sat | E12: =WEEKNUM(C12,1) -> 15 | F12: 23040 | G12: =if(F12<>"",F12*0.05,"") -> 1152 | H12: =F12-G12 -> 21888 | I12: 0 | K12: 0 | N12: =if(or(H12<>"",I12<>"",K12<>""),sum(H12:K12),"") -> 21888
A13: 12 | B13: =TEXT(C13,"MM")&"-"&text(C13,"MMM") -> 04-Apr | C13: 45760 | D13: =text(C13,"ddd") -> Sun | E13: =WEEKNUM(C13,1) -> 16 | F13: 19155 | G13: =if(F13<>"",F13*0.05,"") -> 957.75 | H13: =F13-G13 -> 18197.25 | I13: 0 | K13: 0 | N13: =if(or(H13<>"",I13<>"",K13<>""),sum(H13:K13),"") -> 18197.25
... A29: 28 | B29: =TEXT(C29,"MM")&"-"&text(C29,"MMM") -> 04-Apr | C29: 45776 | D29: =text(C29,"ddd") -> Tue | E29: =WEEKNUM(C29,1) -> 18 | F29: 20695 | G29: =if(F29<>"",F29*0.05,"") -> 1034.75 | H29: =F29-G29 -> 19660.25 | I29: 0 | K29: 0 | N29: =if(or(H29<>"",I29<>"",K29<>""),sum(H29:K29),"") -> 19660.25
A30: 29 | B30: =TEXT(C30,"MM")&"-"&text(C30,"MMM") -> 04-Apr | C30: 45777 | D30: =text(C30,"ddd") -> Wed | E30: =WEEKNUM(C30,1) -> 18 | F30: 37420 | G30: =if(F30<>"",F30*0.05,"") -> 1871 | H30: =F30-G30 -> 35549 | I30: 0 | K30: 0 | N30: =if(or(H30<>"",I30<>"",K30<>""),sum(H30:K30),"") -> 35549 | P30: 635558
A31: 30 | B31: =TEXT(C31,"MM")&"-"&text(C31,"MMM") -> 05-May | C31: 45778 | D31: =text(C31,"ddd") -> Thu | E31: =WEEKNUM(C31,1) -> 18 | F31: 27400 | G31: =if(F31<>"",F31*0.05,"") -> 1370 | H31: =F31-G31 -> 26030 | I31: 0 | K31: 0 | N31: =if(or(H31<>"",I31<>"",K31<>""),sum(H31:K31),"") -> 26030
A32: 31 | B32: =TEXT(C32,"MM")&"-"&text(C32,"MMM") -> 05-May | C32: 45779 | D32: =text(C32,"ddd") -> Fri | E32: =WEEKNUM(C32,1) -> 18 | F32: 28540 | G32: =if(F32<>"",F32*0.05,"") -> 1427 | H32: =F32-G32 -> 27113 | I32: 0 | K32: 0 | N32: =if(or(H32<>"",I32<>"",K32<>""),sum(H32:K32),"") -> 27113
A33: 32 | B33: =TEXT(C33,"MM")&"-"&text(C33,"MMM") -> 05-May | C33: 45780 | D33: =text(C33,"ddd") -> Sat | E33: =WEEKNUM(C33,1) -> 18 | F33: 34760 | G33: =if(F33<>"",F33*0.05,"") -> 1738 | H33: =F33-G33 -> 33022 | I33: 0 | K33: 0 | N33: =if(or(H33<>"",I33<>"",K33<>""),sum(H33:K33),"") -> 33022
A34: 33 | B34: =TEXT(C34,"MM")&"-"&text(C34,"MMM") -> 05-May | C34: 45781 | D34: =text(C34,"ddd") -> Sun | E34: =WEEKNUM(C34,1) -> 19 | F34: 0 | G34: =if(F34<>"",F34*0.05,"") -> 0 | H34: =F34-G34 -> 0 | I34: 0 | K34: 0 | N34: =if(or(H34<>"",I34<>"",K34<>""),sum(H34:K34),"") -> 0
A35: 34 | B35: =TEXT(C35,"MM")&"-"&text(C35,"MMM") -> 05-May | C35: 45782 | D35: =text(C35,"ddd") -> Mon | E35: =WEEKNUM(C35,1) -> 19 | F35: 28428 | G35: =if(F35<>"",F35*0.05,"") -> 1421.4 | H35: =F35-G35 -> 27006.6 | I35: 0 | K35: 0 | N35: =if(or(H35<>"",I35<>"",K35<>""),sum(H35:K35),"") -> 27006.6
A36: 35 | B36: =TEXT(C36,"MM")&"-"&text(C36,"MMM") -> 05-May | C36: 45783 | D36: =text(C36,"ddd") -> Tue | E36: =WEEKNUM(C36,1) -> 19 | F36: 26020 | G36: =if(F36<>"",F36*0.05,"") -> 1301 | H36: =F36-G36 -> 24719 | I36: 0 | K36: 0 | N36: =if(or(H36<>"",I36<>"",K36<>""),sum(H36:K36),"") -> 24719
A37: 36 | B37: =TEXT(C37,"MM")&"-"&text(C37,"MMM") -> 05-May | C37: 45784 | D37: =text(C37,"ddd") -> Wed | E37: =WEEKNUM(C37,1) -> 19 | F37: 22465 | G37: =if(F37<>"",F37*0.05,"") -> 1123.25 | H37: =F37-G37 -> 21341.75 | I37: 0 | K37: 0 | N37: =if(or(H37<>"",I37<>"",K37<>""),sum(H37:K37),"") -> 21341.75
A38: 37 | B38: =TEXT(C38,"MM")&"-"&text(C38,"MMM") -> 05-May | C38: 45785 | D38: =text(C38,"ddd") -> Thu | E38: =WEEKNUM(C38,1) -> 19 | F38: 14110 | G38: =if(F38<>"",F38*0.05,"") -> 705.5 | H38: =F38-G38 -> 13404.5 | I38: 0 | K38: 0 | N38: =if(or(H38<>"",I38<>"",K38<>""),sum(H38:K38),"") -> 13404.5
A39: 38 | B39: =TEXT(C39,"MM")&"-"&text(C39,"MMM") -> 05-May | C39: 45786 | D39: =text(C39,"ddd") -> Fri | E39: =WEEKNUM(C39,1) -> 19 | F39: 39260 | G39: =if(F39<>"",F39*0.05,"") -> 1963 | H39: =F39-G39 -> 37297 | I39: 0 | K39: 0 | N39: =if(or(H39<>"",I39<>"",K39<>""),sum(H39:K39),"") -> 37297
A40: 39 | B40: =TEXT(C40,"MM")&"-"&text(C40,"MMM") -> 05-May | C40: 45787 | D40: =text(C40,"ddd") -> Sat | E40: =WEEKNUM(C40,1) -> 19 | F40: 23155 | G40: =if(F40<>"",F40*0.05,"") -> 1157.75 | H40: =F40-G40 -> 21997.25 | I40: 0 | K40: 0 | N40: =if(or(H40<>"",I40<>"",K40<>""),sum(H40:K40),"") -> 21997.25
A41: 40 | B41: =TEXT(C41,"MM")&"-"&text(C41,"MMM") -> 05-May | C41: 45788 | D41: =text(C41,"ddd") -> Sun | E41: =WEEKNUM(C41,1) -> 20 | F41: 0 | G41: =if(F41<>"",F41*0.05,"") -> 0 | H41: =F41-G41 -> 0 | I41: 0 | K41: 0 | N41: =if(or(H41<>"",I41<>"",K41<>""),sum(H41:K41),"") -> 0
A42: 41 | B42: =TEXT(C42,"MM")&"-"&text(C42,"MMM") -> 05-May | C42: 45789 | D42: =text(C42,"ddd") -> Mon | E42: =WEEKNUM(C42,1) -> 20 | F42: 19740 | G42: =if(F42<>"",F42*0.05,"") -> 987 | H42: =F42-G42 -> 18753 | I42: 0 | K42: 0 | N42: =if(or(H42<>"",I42<>"",K42<>""),sum(H42:K42),"") -> 18753
... A60: 59 | B60: =TEXT(C60,"MM")&"-"&text(C60,"MMM") -> 05-May | C60: 45807 | D60: =text(C60,"ddd") -> Fri | E60: =WEEKNUM(C60,1) -> 22 | F60: 33580 | G60: =if(F60<>"",F60*0.05,"") -> 1679 | H60: =F60-G60 -> 31901 | I60: 2812 | K60: 0 | N60: =if(or(H60<>"",I60<>"",K60<>""),sum(H60:K60),"") -> 34713
A61: 60 | B61: =TEXT(C61,"MM")&"-"&text(C61,"MMM") -> 05-May | C61: 45808 | D61: =text(C61,"ddd") -> Sat | E61: =WEEKNUM(C61,1) -> 22 | F61: 38090 | G61: =if(F61<>"",F61*0.05,"") -> 1904.5 | H61: =F61-G61 -> 36185.5 | I61: 5279 | K61: 0 | N61: =if(or(H61<>"",I61<>"",K61<>""),sum(H61:K61),"") -> 41464.5 | P61: 696194
A62: 61 | B62: =TEXT(C62,"MM")&"-"&text(C62,"MMM") -> 06-Jun | C62: 45809 | D62: =text(C62,"ddd") -> Sun | E62: =WEEKNUM(C62,1) -> 23 | F62: 0 | G62: =if(F62<>"",F62*0.05,"") -> 0 | H62: =F62-G62 -> 0 | I62: 0 | K62: 0 | N62: =if(or(H62<>"",I62<>"",K62<>""),sum(H62:K62),"") -> 0
A63: 62 | B63: =TEXT(C63,"MM")&"-"&text(C63,"MMM") -> 06-Jun | C63: 45810 | D63: =text(C63,"ddd") -> Mon | E63: =WEEKNUM(C63,1) -> 23 | F63: 7010 | G63: =if(F63<>"",F63*0.05,"") -> 350.5 | H63: =F63-G63 -> 6659.5 | I63: 2390 | K63: 0 | N63: =if(or(H63<>"",I63<>"",K63<>""),sum(H63:K63),"") -> 9049.5
A64: 63 | B64: =TEXT(C64,"MM")&"-"&text(C64,"MMM") -> 06-Jun | C64: 45811 | D64: =text(C64,"ddd") -> Tue | E64: =WEEKNUM(C64,1) -> 23 | F64: 43200 | G64: =if(F64<>"",F64*0.05,"") -> 2160 | H64: =F64-G64 -> 41040 | I64: 4216 | K64: 0 | N64: =if(or(H64<>"",I64<>"",K64<>""),sum(H64:K64),"") -> 45256
A65: 64 | B65: =TEXT(C65,"MM")&"-"&text(C65,"MMM") -> 06-Jun | C65: 45812 | D65: =text(C65,"ddd") -> Wed | E65: =WEEKNUM(C65,1) -> 23 | F65: 17150 | G65: =if(F65<>"",F65*0.05,"") -> 857.5 | H65: =F65-G65 -> 16292.5 | I65: 5635 | K65: 0 | N65: =if(or(H65<>"",I65<>"",K65<>""),sum(H65:K65),"") -> 21927.5
A66: 65 | B66: =TEXT(C66,"MM")&"-"&text(C66,"MMM") -> 06-Jun | C66: 45813 | D66: =text(C66,"ddd") -> Thu | E66: =WEEKNUM(C66,1) -> 23 | F66: 24722 | G66: =if(F66<>"",F66*0.05,"") -> 1236.1 | H66: =F66-G66 -> 23485.9 | I66: 5683 | K66: 0 | N66: =if(or(H66<>"",I66<>"",K66<>""),sum(H66:K66),"") -> 29168.9
A67: 66 | B67: =TEXT(C67,"MM")&"-"&text(C67,"MMM") -> 06-Jun | C67: 45814 | D67: =text(C67,"ddd") -> Fri | E67: =WEEKNUM(C67,1) -> 23 | F67: 25380 | G67: =if(F67<>"",F67*0.05,"") -> 1269 | H67: =F67-G67 -> 24111 | I67: 3131 | K67: 0 | N67: =if(or(H67<>"",I67<>"",K67<>""),sum(H67:K67),"") -> 27242
A68: 67 | B68: =TEXT(C68,"MM")&"-"&text(C68,"MMM") -> 06-Jun | C68: 45815 | D68: =text(C68,"ddd") -> Sat | E68: =WEEKNUM(C68,1) -> 23 | F68: 37650 | G68: =if(F68<>"",F68*0.05,"") -> 1882.5 | H68: =F68-G68 -> 35767.5 | I68: 7465 | K68: 0 | N68: =if(or(H68<>"",I68<>"",K68<>""),sum(H68:K68),"") -> 43232.5
A69: 68 | B69: =TEXT(C69,"MM")&"-"&text(C69,"MMM") -> 06-Jun | C69: 45816 | D69: =text(C69,"ddd") -> Sun | E69: =WEEKNUM(C69,1) -> 24 | F69: 0 | G69: =if(F69<>"",F69*0.05,"") -> 0 | H69: =F69-G69 -> 0 | I69: 0 | K69: 0 | N69: =if(or(H69<>"",I69<>"",K69<>""),sum(H69:K69),"") -> 0
A70: 69 | B70: =TEXT(C70,"MM")&"-"&text(C70,"MMM") -> 06-Jun | C70: 45817 | D70: =text(C70,"ddd") -> Mon | E70: =WEEKNUM(C70,1) -> 24 | F70: 15615 | G70: =if(F70<>"",F70*0.05,"") -> 780.75 | H70: =F70-G70 -> 14834.25 | I70: 2458 | K70: 0 | N70: =if(or(H70<>"",I70<>"",K70<>""),sum(H70:K70),"") -> 17292.25
A71: 70 | B71: =TEXT(C71,"MM")&"-"&text(C71,"MMM") -> 06-Jun | C71: 45818 | D71: =text(C71,"ddd") -> Tue | E71: =WEEKNUM(C71,1) -> 24 | F71: 15000 | G71: =if(F71<>"",F71*0.05,"") -> 750 | H71: =F71-G71 -> 14250 | I71: 6227 | K71: 0 | N71: =if(or(H71<>"",I71<>"",K71<>""),sum(H71:K71),"") -> 20477
A72: 71 | B72: =TEXT(C72,"MM")&"-"&text(C72,"MMM") -> 06-Jun | C72: 45819 | D72: =text(C72,"ddd") -> Wed | E72: =WEEKNUM(C72,1) -> 24 | F72: 21170 | G72: =if(F72<>"",F72*0.05,"") -> 1058.5 | H72: =F72-G72 -> 20111.5 | I72: 3671 | K72: 0 | N72: =if(or(H72<>"",I72<>"",K72<>""),sum(H72:K72),"") -> 23782.5
...

Sheet MenuUpdater
A1: Sl. | B1: Item ID | C1: Category | D1: Item Name | E1: Variation | F1: Online Display Name | G1: Item Type | H1: Price | I1: Description | J1: SwiggyPrice | K1: SwiggyIncome | L1: Dietary | M1: Short Code | N1: Sap Code | O1: HSN Code | P1: Weight | Q1: Weight Unit | R1: Rank | S1: Packing Charges | T1: Expose in Captain | U1: Goods/Services | V1: Short Code Two | W1: Allow Decimal Qty | X1: Manufacturing Date (DD-MM-YYYY) | Y1: Expiry Date (DD-MM-YYYY)
A2: 1 | B2: 154634344 | C2: Western | D2: Cajun Fried Prawns | G2: item | H2: 380 | I2: =H2+H2*(1/(0.78)-1) -> 487.17949 | L2: non-veg | M2: ~1 | R2: 1 | S2: 0 | T2: Yes | W2: Yes
A3: 2 | B3: 154634345 | C3: Western | D3: Moroccan Meat Balls | G3: item | H3: 360 | I3: =H3+H3*(1/(1-0.22)-1) -> 461.53846 | L3: non-veg | M3: ~2 | R3: 1 | S3: 0 | T3: Yes | W3: Yes
A4: 3 | B4: 154634346 | C4: Western | D4: Jamaican Chicken Skewer | G4: item | H4: 310 | I4: =H4+H4*(1/(1-0.22)-1) -> 397.4359 | L4: non-veg | M4: ~3 | R4: 1 | S4: 0 | T4: Yes | W4: Yes
A5: 4 | B5: 154634347 | C5: Western | D5: Spicy Corn & Cheese Balls | G5: item | H5: 310 | I5: =H5+H5*(1/(1-0.22)-1) -> 397.4359 | L5: veg | M5: ~4 | R5: 1 | S5: 0 | T5: Yes | W5: Yes
A6: 5 | B6: 154634348 | C6: Western | D6: Nachos With Confit Tomato Salsa | G6: item | H6: 260 | I6: =H6+H6*(1/(1-0.22)-1) -> 333.33333 | L6: veg | M6: ~5 | R6: 1 | S6: 0 | T6: Yes | W6: Yes
A7: 6 | B7: 154634349 | C7: Pastas | D7: Pasta Arabiata | G7: item | H7: 340 | I7: =H7+H7*(1/(1-0.22)-1) -> 435.89744 | L7: veg | M7: ~6 | R7: 1 | S7: 0 | T7: Yes | W7: Yes
A8: 7 | B8: 154634350 | C8: Pastas | D8: Classic Pasta | G8: item | H8: 470 | I8: =H8+H8*(1/(1-0.22)-1) -> 602.5641 | L8: non-veg | M8: ~8 | R8: 1 | S8: 0 | T8: Yes | W8: Yes
A9: 8 | B9: 154634351 | C9: Wraps/Burger | D9: Mexican Tostadas | G9: item | H9: 380 | I9: =H9+H9*(1/(1-0.22)-1) -> 487.17949 | L9: veg | M9: ~9 | R9: 1 | S9: 0 | T9: Yes | W9: Yes
A10: 9 | B10: 154634352 | C10: Wraps/Burger | D10: Chicken Quesadilla | G10: item | H10: 420 | I10: =H10+H10*(1/(1-0.22)-1) -> 538.46154 | L10: non-veg | M10: ~10 | R10: 1 | S10: 0 | T10: Yes | W10: Yes
A11: 10 | B11: 154634353 | C11: Mains | D11: Stuffed Chicken Roulade | G11: item | H11: 490 | I11: =H11+H11*(1/(1-0.22)-1) -> 628.20513 | L11: non-veg | M11: stuffed chicken roul | R11: 1 | S11: 0 | T11: Yes | W11: Yes
A12: 11 | B12: 154634354 | C12: Mains | D12: Grilled Beef Tenderloin | G12: item | H12: 520 | I12: =H12+H12*(1/(1-0.22)-1) -> 666.66667 | L12: non-veg | M12: grilled beef tenderl | R12: 1 | S12: 0 | T12: Yes | W12: Yes
A13: 12 | B13: 154634355 | C13: Asian | D13: Asian Bbq Pork Ribs | G13: item | H13: 380 | I13: =H13+H13*(1/(1-0.22)-1) -> 487.17949 | L13: non-veg | M13: ~14 | R13: 1 | S13: 0 | T13: Yes | W13: Yes
A14: 13 | B14: 154634356 | C14: Mains | D14: Shepherds Pie | G14: item | H14: 520 | I14: =H14+H14*(1/(1-0.22)-1) -> 666.66667 | L14: non-veg | M14: shepherds pie | R14: 1 | S14: 0 | T14: Yes | W14: Yes
... A35: 34 | B35: 154634377 | C35: Authentic Japanese Sushi | D35: Crunchy Caprese Roll | G35: item | H35: 450 | I35: =H35+H35*(1/(1-0.22)-1) -> 576.92308 | L35: veg | M35: ~36 | R35: 1 | S35: 0 | T35: Yes | W35: Yes
A36: 35 | B36: 154634378 | C36: Veg Pizzas | D36: Wild Mushroom | G36: item | H36: 0 | I36: =H36+H36*(1/(1-0.22)-1) -> 0 | K36: =if(J36<>"",J36-J36*20%,"") | L36: veg | M36: ~37 | R36: 1 | S36: 0 | T36: Yes | W36: Yes
A37: 36 | B37: 154634412 | C37: Veg Pizzas | D37: Wild Mushroom (8 Inch) | E37: 8 Inch | G37: variation | H37: 375 | I37: =H37+H37*(1/(1-0.22)-1) -> 480.76923 | K37: =if(J37<>"",J37-J37*20%,"") | L37: veg | R37: 1 | S37: 0 | T37: Yes | W37: Yes
A38: 37 | B38: 154634413 | C38: Veg Pizzas | D38: Wild Mushroom (10 Inch) | E38: 10 Inch | G38: variation | H38: 525 | I38: =H38+H38*(1/(1-0.22)-1) -> 673.07692 | K38: =if(J38<>"",J38-J38*20%,"") | L38: veg | R38: 1 | S38: 0 | T38: Yes | W38: Yes
A39: 38 | B39: 154634414 | C39: Veg Pizzas | D39: Wild Mushroom (12 Inch) | E39: 12 Inch | G39: variation | H39: 650 | I39: =H39+H39*(1/(1-0.22)-1) -> 833.33333 | K39: =if(J39<>"",J39-J39*20%,"") | L39: veg | R39: 1 | S39: 0 | T39: Yes | W39: Yes
A40: 39 | B40: 154634379 | C40: Veg Pizzas | D40: Melanzane | G40: item | H40: 0 | I40: =H40+H40*(1/(1-0.22)-1) -> 0 | L40: veg | M40: ~38 | R40: 1 | S40: 0 | T40: Yes | W40: Yes
A41: 40 | B41: 154634415 | C41: Veg Pizzas | D41: Melanzane (8 Inch) | E41: 8 Inch | G41: variation | H41: 350 | I41: =H41+H41*(1/(1-0.22)-1) -> 448.71795 | K41: =if(J41<>"",J41-J41*20%,"") | L41: veg | R41: 1 | S41: 0 | T41: Yes | W41: Yes
A42: 41 | B42: 154634416 | C42: Veg Pizzas | D42: Melanzane (10 Inch) | E42: 10 Inch | G42: variation | H42: 450 | I42: =H42+H42*(1/(1-0.22)-1) -> 576.92308 | K42: =if(J42<>"",J42-J42*20%,"") | L42: veg | R42: 1 | S42: 0 | T42: Yes | W42: Yes
A43: 42 | B43: 154634417 | C43: Veg Pizzas | D43: Melanzane (12 Inch) | E43: 12 Inch | G43: variation | H43: 550 | I43: =H43+H43*(1/(1-0.22)-1) -> 705.12821 | K43: =if(J43<>"",J43-J43*20%,"") | L43: veg | R43: 1 | S43: 0 | T43: Yes | W43: Yes
A44: 43 | B44: 154634380 | C44: Veg Pizzas | D44: Premavera | G44: item | H44: 0 | I44: =H44+H44*(1/(1-0.22)-1) -> 0 | L44: veg | M44: ~39 | R44: 1 | S44: 0 | T44: Yes | W44: Yes
A45: 44 | B45: 154634418 | C45: Veg Pizzas | D45: Premavera (8 Inch) | E45: 8 Inch | G45: variation | H45: 375 | I45: =H45+H45*(1/(1-0.22)-1) -> 480.76923 | K45: =if(J45<>"",J45-J45*20%,"") | L45: veg | R45: 1 | S45: 0 | T45: Yes | W45: Yes
A46: 45 | B46: 154634419 | C46: Veg Pizzas | D46: Premavera (10 Inch) | E46: 10 Inch | G46: variation | H46: 525 | I46: =H46+H46*(1/(1-0.22)-1) -> 673.07692 | K46: =if(J46<>"",J46-J46*20%,"") | L46: veg | R46: 1 | S46: 0 | T46: Yes | W46: Yes
A47: 46 | B47: 154634420 | C47: Veg Pizzas | D47: Premavera (12 Inch) | E47: 12 Inch | G47: variation | H47: 650 | I47: =H47+H47*(1/(1-0.22)-1) -> 833.33333 | K47: =if(J47<>"",J47-J47*20%,"") | L47: veg | R47: 1 | S47: 0 | T47: Yes | W47: Yes
A48: 47 | B48: 154634381 | C48: Veg Pizzas | D48: Grilled Paneer | G48: item | H48: 0 | I48: =H48+H48*(1/(1-0.22)-1) -> 0 | L48: veg | M48: ~40 | R48: 1 | S48: 0 | T48: Yes | W48: Yes
A49: 48 | B49: 154634421 | C49: Veg Pizzas | D49: Grilled Paneer (8 Inch) | E49: 8 Inch | G49: variation | H49: 375 | I49: =H49+H49*(1/(1-0.22)-1) -> 480.76923 | K49: =if(J49<>"",J49-J49*20%,"") | L49: veg | R49: 1 | S49: 0 | T49: Yes | W49: Yes
A50: 49 | B50: 154634422 | C50: Veg Pizzas | D50: Grilled Paneer (10 Inch) | E50: 10 Inch | G50: variation | H50: 525 | I50: =H50+H50*(1/(1-0.22)-1) -> 673.07692 | K50: =if(J50<>"",J50-J50*20%,"") | L50: veg | R50: 1 | S50: 0 | T50: Yes | W50: Yes
A51: 50 | B51: 154634423 | C51: Veg Pizzas | D51: Grilled Paneer (12 Inch) | E51: 12 Inch | G51: variation | H51: 650 | I51: =H51+H51*(1/(1-0.22)-1) -> 833.33333 | K51: =if(J51<>"",J51-J51*20%,"") | L51: veg | R51: 1 | S51: 0 | T51: Yes | W51: Yes
A52: 51 | B52: 154634382 | C52: Veg Pizzas | D52: Margherita | G52: item | H52: 0 | I52: =H52+H52*(1/(1-0.22)-1) -> 0 | L52: veg | M52: ~41 | R52: 1 | S52: 0 | T52: Yes | W52: Yes
A53: 52 | B53: 154634424 | C53: Veg Pizzas | D53: Margherita (8 Inch) | E53: 8 Inch | G53: variation | H53: 325 | I53: =H53+H53*(1/(1-0.22)-1) -> 416.66667 | K53: =if(J53<>"",J53-J53*20%,"") | L53: veg | R53: 1 | S53: 0 | T53: Yes | W53: Yes
A54: 53 | B54: 154634425 | C54: Veg Pizzas | D54: Margherita (10 Inch) | E54: 10 Inch | G54: variation | H54: 450 | I54: =H54+H54*(1/(1-0.22)-1) -> 576.92308 | K54: =if(J54<>"",J54-J54*20%,"") | L54: veg | R54: 1 | S54: 0 | T54: Yes | W54: Yes
A55: 54 | B55: 154634426 | C55: Veg Pizzas | D55: Margherita (12 Inch) | E55: 12 Inch | G55: variation | H55: 600 | I55: =H55+H55*(1/(1-0.22)-1) -> 769.23077 | K55: =if(J55<>"",J55-J55*20%,"") | L55: veg | R55: 1 | S55: 0 | T55: Yes | W55: Yes
A56: 55 | B56: 154634383 | C56: Veg Pizzas | D56: Quattro Formaggi | G56: item | H56: 0 | I56: =H56+H56*(1/(1-0.22)-1) -> 0 | L56: veg | M56: ~42 | R56: 1 | S56: 0 | T56: Yes | W56: Yes
A57: 56 | B57: 154634427 | C57: Veg Pizzas | D57: Quattro Formaggi (8 Inch) | E57: 8 Inch | G57: variation | H57: 425 | I57: =H57+H57*(1/(1-0.22)-1) -> 544.87179 | K57: =if(J57<>"",J57-J57*20%,"") | L57: veg | R57: 1 | S57: 0 | T57: Yes | W57: Yes
A58: 57 | B58: 154634428 | C58: Veg Pizzas | D58: Quattro Formaggi (10 Inch) | E58: 10 Inch | G58: variation | H58: 575 | I58: =H58+H58*(1/(1-0.22)-1) -> 737.17949 | K58: =if(J58<>"",J58-J58*20%,"") | L58: veg | R58: 1 | S58: 0 | T58: Yes | W58: Yes
A59: 58 | B59: 154634429 | C59: Veg Pizzas | D59: Quattro Formaggi (12 Inch) | E59: 12 Inch | G59: variation | H59: 725 | I59: =H59+H59*(1/(1-0.22)-1) -> 929.48718 | K59: =if(J59<>"",J59-J59*20%,"") | L59: veg | R59: 1 | S59: 0 | T59: Yes | W59: Yes
A60: 59 | B60: 154634384 | C60: Non Veg Pizzas | D60: Italian Salsiccia | G60: item | H60: 0 | I60: =H60+H60*(1/(1-0.22)-1) -> 0 | L60: non-veg | M60: ~43 | R60: 1 | S60: 0 | T60: Yes | W60: Yes
...

Sheet Swiggy Order Summary
A4: PaymentID | B4: Start Date | C4: End Date | D4: No. of Orders | E4: Total Sales | F4: Sw_Order | G4: Sw_Total | H4: Sw_ServiceFee | I4: Sw_Other | J4: Sw_TCS | K4: SW_Payable | L4: SW_Differnce | M4: ActualDifference | N4: Swiggy%
A5: APR16 | B5: 45753 | C5: 45760 | D5: =COUNTIFS(SwiggyOrders[Order Delivery Time],">="&DATEVALUE(B5),SwiggyOrders[Order Delivery Time],"<="&DATEVALUE(C5)) -> 7 | E5: =SUMIFS(SwiggyOrders[Total Bill Amount],SwiggyOrders[Order Delivery Time],">="&DATEVALUE(B5),SwiggyOrders[Order Delivery Time],"<="&DATEVALUE(C5)) -> 6872 | F5: 7 | G5: 6872.28 | H5: 973.15 | I5: 1506.25 | J5: 6.55 | K5: 4386.32 | L5: =G5-K5 -> 2485.96 | M5: =E5-K5 -> 2485.68 | N5: =L5/G5 -> 0.3617373
A6: APR23 | B6: 45760 | C6: 45767 | D6: =COUNTIFS(SwiggyOrders[Order Delivery Time],">="&DATEVALUE(B6),SwiggyOrders[Order Delivery Time],"<="&DATEVALUE(C6)) -> 15 | E6: =SUMIFS(SwiggyOrders[Total Bill Amount],SwiggyOrders[Order Delivery Time],">="&DATEVALUE(B6),SwiggyOrders[Order Delivery Time],"<="&DATEVALUE(C6)) -> 13706 | F6: 16 | G6: 13818.11 | H6: 1956.61 | I6: 658 | J6: 13.6 | K6: 11190.28 | L6: =G6-K6 -> 2627.83 | M6: =E6-K6 -> 2515.72 | N6: =L6/G6 -> 0.1901729
A7: APR30 | B7: 45828 | C7: 45835 | D7: =COUNTIFS(SwiggyOrders[Order Delivery Time],">="&DATEVALUE(B7),SwiggyOrders[Order Delivery Time],"<="&DATEVALUE(C7)) -> 45 | E7: =SUMIFS(SwiggyOrders[Total Bill Amount],SwiggyOrders[Order Delivery Time],">="&DATEVALUE(B7),SwiggyOrders[Order Delivery Time],"<="&DATEVALUE(C7)) -> 52771 | F7: 53 | G7: 49381.8 | H7: 6992.35 | I7: 2620.5 | J7: 47.03 | K7: 39721.55 | L7: =G7-K7 -> 9660.25 | M7: =E7-K7 -> 13049.45 | N7: =L7/G7 -> 0.19562369
A8: MAY5 | B8: 45774 | C8: 45777 | D8: =COUNTIFS(SwiggyOrders[Order Delivery Time],">="&DATEVALUE(B8),SwiggyOrders[Order Delivery Time],"<="&DATEVALUE(C8)) -> 10 | E8: =SUMIFS(SwiggyOrders[Total Bill Amount],SwiggyOrders[Order Delivery Time],">="&DATEVALUE(B8),SwiggyOrders[Order Delivery Time],"<="&DATEVALUE(C8)) -> 11511 | F8: 18 | G8: 18711.1 | H8: 2649.41 | I8: 891 | J8: 17.82 | K8: 15152.76 | L8: =G8-K8 -> 3558.34 | M8: =E8-K8 -> -3641.76 | N8: =L8/G8 -> 0.19017268
A9: MAY7 | B9: =C8+1 -> 45778 | C9: 45780 | D9: =COUNTIFS(SwiggyOrders[Order Delivery Time],">="&DATEVALUE(B9),SwiggyOrders[Order Delivery Time],"<="&DATEVALUE(C9)) -> 9 | E9: =SUMIFS(SwiggyOrders[Total Bill Amount],SwiggyOrders[Order Delivery Time],">="&DATEVALUE(B9),SwiggyOrders[Order Delivery Time],"<="&DATEVALUE(C9)) -> 10183 | F9: 15 | G9: 13810.73 | H9: 1955.58 | I9: 1355.65 | J9: 13.15 | K9: 10486.25 | L9: =G9-K9 -> 3324.48 | M9: =E9-K9 -> -303.25 | N9: =L9/G9 -> 0.24071718
A10: MAY14 | B10: =C9+1 -> 45781 | C10: =B10+6 -> 45787 | D10: =COUNTIFS(SwiggyOrders[Order Delivery Time],">="&DATEVALUE(B10),SwiggyOrders[Order Delivery Time],"<="&DATEVALUE(C10)) -> 21 | E10: =SUMIFS(SwiggyOrders[Total Bill Amount],SwiggyOrders[Order Delivery Time],">="&DATEVALUE(B10),SwiggyOrders[Order Delivery Time],"<="&DATEVALUE(C10)) -> 19022 | F10: 24 | G10: 17763.48 | H10: 2522.44 | I10: 845.88 | J10: 16.92 | K10: 14375.22 | L10: =G10-K10 -> 3388.26 | M10: =E10-K10 -> 4646.78 | N10: =L10/G10 -> 0.19074303
A11: MAY21 | B11: =C10+1 -> 45788 | C11: =B11+6 -> 45794 | D11: =COUNTIFS(SwiggyOrders[Order Delivery Time],">="&DATEVALUE(B11),SwiggyOrders[Order Delivery Time],"<="&DATEVALUE(C11)) -> 21 | E11: =SUMIFS(SwiggyOrders[Total Bill Amount],SwiggyOrders[Order Delivery Time],">="&DATEVALUE(B11),SwiggyOrders[Order Delivery Time],"<="&DATEVALUE(C11)) -> 17968 | F11: 24 | G11: 19826.22 | H11: 29 | I11: 1646.1 | J11: 17.71 | K11: 15528.99 | L11: =G11-K11 -> 4297.23 | M11: =E11-K11 -> 2439.01 | N11: =L11/G11 -> 0.2167448
A12: MAY28 | B12: =C11+1 -> 45795 | C12: =B12+6 -> 45801 | D12: =COUNTIFS(SwiggyOrders[Order Delivery Time],">="&DATEVALUE(B12),SwiggyOrders[Order Delivery Time],"<="&DATEVALUE(C12)) -> 21 | E12: =SUMIFS(SwiggyOrders[Total Bill Amount],SwiggyOrders[Order Delivery Time],">="&DATEVALUE(B12),SwiggyOrders[Order Delivery Time],"<="&DATEVALUE(C12)) -> 15230 | G12: 20599 | H12: 2916.74 | I12: 1100.9 | J12: 19.62 | K12: 16561.62 | L12: =G12-K12 -> 4037.38 | M12: =E12-K12 -> -1331.62 | N12: =L12/G12 -> 0.19599883
A13: JUN4 | B13: =C12+1 -> 45802 | C13: =B13+6 -> 45808 | D13: =COUNTIFS(SwiggyOrders[Order Delivery Time],">="&DATEVALUE(B13),SwiggyOrders[Order Delivery Time],"<="&DATEVALUE(C13)) -> 26 | E13: =SUMIFS(SwiggyOrders[Total Bill Amount],SwiggyOrders[Order Delivery Time],">="&DATEVALUE(B13),SwiggyOrders[Order Delivery Time],"<="&DATEVALUE(C13)) -> 26045 | F13: 34 | G13: 30568.8 | H13: 4328.51 | I13: 1455.65 | J13: 29.11 | K13: 24755.42 | L13: =G13-K13 -> 5813.38 | M13: =E13-K13 -> 1289.58 | N13: =L13/G13 -> 0.19017364
A14: JUN11 | B14: =C13+1 -> 45809 | C14: =B14+6 -> 45815 | D14: =COUNTIFS(SwiggyOrders[Order Delivery Time],">="&DATEVALUE(B14),SwiggyOrders[Order Delivery Time],"<="&DATEVALUE(C14)) -> 32 | E14: =SUMIFS(SwiggyOrders[Total Bill Amount],SwiggyOrders[Order Delivery Time],">="&DATEVALUE(B14),SwiggyOrders[Order Delivery Time],"<="&DATEVALUE(C14)) -> 27518 | F14: 42 | G14: 35786.6 | H14: 5067.38 | I14: 5244.12 | J14: 34.08 | K14: 25440.8 | L14: =G14-K14 -> 10345.8 | M14: =E14-K14 -> 2077.2 | N14: =L14/G14 -> 0.28909704
A15: JUN18 | B15: =C14+1 -> 45816 | C15: =B15+6 -> 45822 | D15: =COUNTIFS(SwiggyOrders[Order Delivery Time],">="&DATEVALUE(B15),SwiggyOrders[Order Delivery Time],"<="&DATEVALUE(C15)) -> 36 | E15: =SUMIFS(SwiggyOrders[Total Bill Amount],SwiggyOrders[Order Delivery Time],">="&DATEVALUE(B15),SwiggyOrders[Order Delivery Time],"<="&DATEVALUE(C15)) -> 32893 | F15: 42 | G15: 35084.41 | H15: 4967.94 | I15: 5210.68 | J15: 33.41 | K15: 24872.2 | L15: =G15-K15 -> 10212.21 | M15: =E15-K15 -> 8020.8 | N15: =L15/G15 -> 0.29107544
A16: JUN25 | B16: 45830 | C16: 45838 | D16: =COUNTIFS(SwiggyOrders[Order Delivery Time],">="&DATEVALUE(B16),SwiggyOrders[Order Delivery Time],"<="&DATEVALUE(C16)) -> 47 | E16: =SUMIFS(SwiggyOrders[Total Bill Amount],SwiggyOrders[Order Delivery Time],">="&DATEVALUE(B16),SwiggyOrders[Order Delivery Time],"<="&DATEVALUE(C16)) -> 55945 | F16: 34 | G16: 35177.74 | H16: 4981.2 | I16: 5215.12 | J16: 33.5 | K16: 24947.72 | L16: =G16-K16 -> 10230.02 | M16: =E16-K16 -> 30997.28 | N16: =L16/G16 -> 0.29080947
A17: JUL4 | B17: =C16+1 -> 45839 | C17: =B17+6 -> 45845 | D17: =COUNTIFS(SwiggyOrders[Order Delivery Time],">="&DATEVALUE(B17),SwiggyOrders[Order Delivery Time],"<="&DATEVALUE(C17)) -> 75 | E17: =SUMIFS(SwiggyOrders[Total Bill Amount],SwiggyOrders[Order Delivery Time],">="&DATEVALUE(B17),SwiggyOrders[Order Delivery Time],"<="&DATEVALUE(C17)) -> 80771 | F17: 57 | G17: 61543.62 | H17: 8714.56 | I17: 6470.64 | J17: 58.61 | K17: 46299.56 | L17: =G17-K17 -> 15244.06 | M17: =E17-K17 -> 34471.44 | N17: =L17/G17 -> 0.24769521
A18: JUL9 | B18: =C17+1 -> 45846 | C18: =B18+6 -> 45852 | D18: =COUNTIFS(SwiggyOrders[Order Delivery Time],">="&DATEVALUE(B18),SwiggyOrders[Order Delivery Time],"<="&DATEVALUE(C18)) -> 49 | E18: =SUMIFS(SwiggyOrders[Total Bill Amount],SwiggyOrders[Order Delivery Time],">="&DATEVALUE(B18),SwiggyOrders[Order Delivery Time],"<="&DATEVALUE(C18)) -> 56858 | F18: 57 | G18: 61543.62 | H18: 8714.56 | I18: 6470.64 | J18: 58.61 | K18: 46299.56 | L18: =G18-K18 -> 15244.06 | M18: =E18-K18 -> 10558.44 | N18: =L18/G18 -> 0.24769521
A19: JUL17 | B19: =C18+1 -> 45853 | C19: =B19+6 -> 45859 | D19: =COUNTIFS(SwiggyOrders[Order Delivery Time],">="&DATEVALUE(B19),SwiggyOrders[Order Delivery Time],"<="&DATEVALUE(C19)) -> 0 | E19: =SUMIFS(SwiggyOrders[Total Bill Amount],SwiggyOrders[Order Delivery Time],">="&DATEVALUE(B19),SwiggyOrders[Order Delivery Time],"<="&DATEVALUE(C19)) -> 0 | F19: 57 | G19: 61543.62 | H19: 8714.56 | I19: 6470.64 | J19: 58.61 | K19: 46299.56 | L19: =G19-K19 -> 15244.06 | M19: =E19-K19 -> -46299.56 | N19: =L19/G19 -> 0.24769521

Sheet PL
B2: Philos Delicacy, Kakkanad | H2: 45945 | I2: =H2-TODAY() -> -253
B3: P/L Report
B4: Income | C4: =sum(D5:D7) -> 10753785
C5: Petpooja | D5: =sum(Business[Petpooja]) -> 8457809.2
C6: Swiggy | D6: =sum(Business[Swiggy]) -> 2194226
C7: Direct | D7: =sum(Business[Paper Bill]) -> 101750
B8: Expenses | C8: =sum(D9:D12) -> 9829504.2 | F8: =C8/C4 -> 0.91405064 | H8: Sprite | I8: French Fries | J8: Pizza | K8: Combo Price
C9: Paid Bills | D9: =sumif(Purchase_Register[Paid?], True, Purchase_Register[Amount]) -> 9121117.2 | H9: 20 | I9: 130 | J9: 475 | K9: 499 | L9: 8"
C10: Unpaid Bills | D10: =sumif(Purchase_Register[Paid?], False, Purchase_Register[Amount]) -> 15255 | H10: 12 | I10: 50 | J10: 200 | K10: 262
C11: Loan Repay (Sumit) | D11: 350000
C12: Petty Cash | D12: 343132
B13: Balance | C13: =C4-C8 -> 924280.9 | H13: 40 | I13: 130 | J13: 475 | K13: 499 | L13: 8"
H14: 12 | I14: 50 | J14: 200 | K14: 262
C15: Initial Investment | D15: Yrly Interest (8%) | E15: Mnthly Interest
C16: 3583602 | D16: =C16*0.08 -> 286688.16 | E16: =D16/12 -> 23890.68

Sheet Masters
A1: Vendors | B1: Category
A2: T3 SPECIALITY
A3: MATHA MEATS
A4: GREENZ VEGGIES | F4: Sendry Creditors
A5: POLAR ICE CUBES | F5: Sendry Debtors
A6: HOST VYTILA | F6: Raw Materias
A7: ARACKAL BHARATH GAS | F7: Direct Expenses
A8: TRIO MEATS KTM
A9: DIAMOND
A10: GROW GREENS
A11: UNITED TRADERS KTM
A12: LERA COCA COLA
A13: RIGHT SOLUTION PAPER TISSUE
A14: PETPOOJA
A15: ANGADI SUPERMARKET
A16: WATER SUPPLY
A17: ROYAL KTM
A18: AMAZON
A19: ZEPTO
... A80: CM MARGINE FREE

Sheet Monthly Expenditure Report
F44: Profit/Loss
F45: =E45-B39-C39 -> 855604.95
F46: =E46-D39 -> 763843.55
F47: =E47-E39 -> 898091.1
F48: =E48-F39 -> 1515309.6 | H48: YES Bank | I48: 239408 | K48: Ben | L48: 55000
F49: =E49-F40 -> 1685322.9 | H49: FDRL Bank | I49: 21283 | K49: Philo | L49: 20000
F50: =SUM(F46:F49) -> 4862567.1 | K50: School Fee | L50: 37000
K51: Tithe | L51: 50000
K52: Deopsit (Leena) | L52: 10500
F53: =F49-L53 -> 1342190.9 | K53: Petty Cash | L53: =PL!D12 -> 343132

Sheet Savings
A1: Date | B1: Saved amount | C1: Running Total
A2: 45832 | B2: 4000 | C2: =B2 -> 4000
A3: =A2+1 -> 45833 | B3: =B2 -> 4000 | C3: =C2+B3 -> 8000
A4: 45833 | B4: =B3 -> 4000 | C4: =C3+B4 -> 12000
A5: =A4+1 -> 45834 | B5: =B4 -> 4000 | C5: =C4+B5 -> 16000
A6: 45834 | B6: =B5 -> 4000 | C6: =C5+B6 -> 20000
A7: =A6+1 -> 45835 | B7: =B6 -> 4000 | C7: =C6+B7 -> 24000
A8: 45835 | B8: =B7 -> 4000 | C8: =C7+B8 -> 28000
A9: =A8+1 -> 45836 | B9: =B8 -> 4000 | C9: =C8+B9 -> 32000
A10: 45836 | B10: =B9 -> 4000 | C10: =C9+B10 -> 36000
A11: =A10+1 -> 45837 | B11: =B10 -> 4000 | C11: =C10+B11 -> 40000
A12: 45837 | B12: =B11 -> 4000 | C12: =C11+B12 -> 44000
A13: =A12+1 -> 45838 | B13: =B12 -> 4000 | C13: =C12+B13 -> 48000
A14: 45838 | B14: =B13 -> 4000 | C14: =C13+B14 -> 52000
A15: =A14+1 -> 45839 | B15: =B14 -> 4000 | C15: =C14+B15 -> 56000
A16: 45839 | B16: =B15 -> 4000 | C16: =C15+B16 -> 60000
A17: =A16+1 -> 45840 | B17: =B16 -> 4000 | C17: =C16+B17 -> 64000
A18: 45840 | B18: =B17 -> 4000 | C18: =C17+B18 -> 68000
A19: =A18+1 -> 45841 | B19: =B18 -> 4000 | C19: =C18+B19 -> 72000
A20: 45841 | B20: =B19 -> 4000 | C20: =C19+B20 -> 76000
A21: =A20+1 -> 45842 | B21: =B20 -> 4000 | C21: =C20+B21 -> 80000
A22: 45842 | B22: =B21 -> 4000 | C22: =C21+B22 -> 84000
A23: =A22+1 -> 45843 | B23: =B22 -> 4000 | C23: =C22+B23 -> 88000
A24: 45843 | B24: =B23 -> 4000 | C24: =C23+B24 -> 92000
A25: =A24+1 -> 45844 | B25: =B24 -> 4000 | C25: =C24+B25 -> 96000
A26: 45844 | B26: =B25 -> 4000 | C26: =C25+B26 -> 100000
A27: =A26+1 -> 45845 | B27: =B26 -> 4000 | C27: =C26+B27 -> 104000
A28: 45845 | B28: =B27 -> 4000 | C28: =C27+B28 -> 108000
A29: =A28+1 -> 45846 | B29: =B28 -> 4000 | C29: =C28+B29 -> 112000
A30: 45846 | B30: =B29 -> 4000 | C30: =C29+B30 -> 116000
A31: =A30+1 -> 45847 | B31: =B30 -> 4000 | C31: =C30+B31 -> 120000
A32: 45847 | B32: =B31 -> 4000 | C32: =C31+B32 -> 124000
A33: =A32+1 -> 45848 | B33: =B32 -> 4000 | C33: =C32+B33 -> 128000
A34: 45848 | B34: =B33 -> 4000 | C34: =C33+B34 -> 132000
A35: =A34+1 -> 45849 | B35: =B34 -> 4000 | C35: =C34+B35 -> 136000
A36: 45849 | B36: =B35 -> 4000 | C36: =C35+B36 -> 140000
A37: =A36+1 -> 45850 | B37: =B36 -> 4000 | C37: =C36+B37 -> 144000
A38: 45850 | B38: =B37 -> 4000 | C38: =C37+B38 -> 148000
A39: =A38+1 -> 45851 | B39: =B38 -> 4000 | C39: =C38+B39 -> 152000
A40: 45851 | B40: =B39 -> 4000 | C40: =C39+B40 -> 156000
...

Sheet Sheet3
A1: AL SHAH ENTERPRISES | B1: Utensils
A2: Angadi supermarket | B2: lemon | H2: 99 | I2: 45762 | J2: Greenz Veggies | K2: tomato | L2: 1660 | M2: FALSE | P2: 5
A3: Bestocare Traders | B3: Tuna | H3: 154 | I3: 45762 | J3: Greenz Veggies | K3: veggies | L3: 1660 | M3: FALSE | P3: 5
A4: Diamond | B4: Floor cleaner | H4: 04-Apr | I4: 157 | J4: 45764 | K4: Greenz Veggies | L4: veggies | M4: 1538 | N4: FALSE | Q4: 5
A5: Diamond | B5: juice shaker
A6: Diamond | B6: skillet, ice bucket
A7: Diamond | B7: wrap paper
A8: EandE agencies | B8: soda
A9: Glow Green | B9: Sunflower
A10: Greenz Veggies | B10: brocoli
A11: Greenz Veggies | B11: tomato
A12: Greenz Veggies | B12: veggies
A13: Grow greens | B13: micro greens
A14: Grow greens | B14: Sunflower
A15: Hygiene fresh | B15: cap
A16: LERA | B16: soda,sprite
... A60: United traders Kottayam | B60: wheet flour

Sheet Sheet4
A2: Vendors | B2: Category | E2: 10.52 | F2: 1400
A3: T3 Speciality | B3: Meat & Seafood | E3: 3.46 | F3: =F2/E2 -> 133.07985
A4: Matha meats | B4: Meat & Seafood | F4: =F2/E3 -> 404.62428
A5: Greenz Veggies | B5: Vegetables | F5: 0.11
A6: Polar Ice Cubes | B6: Beverages & Ice | F6: =F4*F5 -> 44.508671 | G6: 700 | H6: =sum(F6:F11) -> 253.59958 | I6: =F6 -> 44.508671 | K6: 26320
A7: Green valley water | B7: Beverages & Ice | E7: 490 | F7: =E7/5.5 -> 89.090909 | H7: =H6/G6 -> 0.36228511 | I7: =E7/6 -> 81.666667 | K7: 32
A8: STAFF SALARY | B8: Salaries | F8: 15 | H8: =sum(I6:I11) -> 206.17534 | I8: 15 | K8: =K6/K7 -> 822.5
A9: CAREVELLO (PIZZA BOX) | B9: Other | E9: 437.5 | F9: 15 | H9: =H8/G6 -> 0.2945362 | I9: 15
A10: Trio meats Kottayam | B10: Meat & Seafood | E10: =0.12 -> 0.12 | F10: 70 | I10: 40
A11: Chicken Factory | B11: Meat & Seafood | E11: =E9*E10 -> 52.5 | F11: 20 | I11: 10
A12: Best Fish | B12: Meat & Seafood
A13: Fruits and Vegetables | B13: Vegetables
A14: Elite foods | B14: Other
A15: Bismi water | B15: Beverages & Ice
A16: Royal Bakers | B16: Other
A17: Chungath Poultry Mart | B17: Meat & Seafood
A18: Haritha Vegetables | B18: Vegetables
A19: Thejaswi fish stall | B19: Meat & Seafood
A20: Cochin Frozen Foods | B20: Meat & Seafood
A21: Nandanam Vegetables | B21: Vegetables
A22: Apsara Ice Cream | B22: Beverages & Ice
A23: C.A.Poultry Farm | B23: Meat & Seafood
... A38: Sowparnika | B38: Other

Sheet Pizza Costing
B1: BBQ | C1: Chef Spl | D1: Porchetta | E1: Classic Pork | F1: Chef Spl (8")
A2: Chicken | C2: 45 | D2: 0 | E2: 0 | F2: =55*N3 -> 22.22 | L2: Cheese | M2: 490 | N2: =M2/1000 -> 0.49
A3: Beef | C3: 35 | D3: 0 | E3: 0 | F3: =180*N6 -> 18 | L3: Chicken | M3: 404 | N3: =M3/1000 -> 0.404
A4: Pork | C4: 0 | D4: 127 | E4: 127 | F4: 0 | L4: C. Pepperoni | M4: 633 | N4: =M4/1000 -> 0.633
A5: Pepperoni | C5: 20 | D5: 0 | E5: 0 | F5: =16*N4 -> 10.128 | L5: Imp. Cheese | M5: 565 | N5: =M5/1000 -> 0.565
A6: Bacon | B6: 0 | C6: 0 | D6: 0 | F6: 0 | L6: Beef | M6: 100 | N6: =M6/1000 -> 0.1
A7: Veggies | C7: 0 | D7: 0 | E7: 0 | F7: 0 | I7: Mushroom | J7: 20 | L7: Olives | M7: 762 | N7: =M7/1520 -> 0.50131579
A8: Cheese | C8: =0.49*180 -> 88.2 | D8: 88.2 | E8: 88.2 | F8: =80*N2 -> 39.2 | I8: Olives | J8: 15 | K8: =N7*J8 -> 7.5197368 | L8: Mushroom | M8: 80 | N8: =M8/400 -> 0.2
A9: Imp. Cheese | C9: 2 | D9: 2 | E9: =4*N5 -> 2.26 | F9: =2*N5 -> 1.13 | H9: 565 | I9: Imp. Cheese | J9: 2 | L9: P. Pepperoni
A10: Dough | C10: 15 | D10: 15 | E10: 15 | F10: 10 | L10: Origano | M10: 480 | N10: =M10/500 -> 0.96
A11: Sauce | C11: 15 | D11: 15 | E11: 15 | F11: 10 | L11: Olive Oil
A12: Olives | B12: 9 | C12: 9 | D12: 9 | E12: 9 | F12: =6*N7 -> 3.0078947
A13: Mushroom | C13: 10 | D13: 10 | E13: 10 | F13: =20*N8 -> 4
A14: Toppings | C14: 20 | D14: 20 | E14: 20 | F14: =16*N8 -> 3.2
A15: Olive Oil | B15: 8 | C15: 8 | D15: 8 | E15: 8 | F15: 5
A16: Origano | B16: 5 | C16: 2 | D16: 2 | E16: 2 | F16: 1
A17: Tomato Confit | B17: 10 | C17: 10 | D17: 10 | E17: 10 | F17: 5
B18: =SUM(B2:B17) -> 32 | C18: =SUM(C2:C17) -> 279.2 | D18: =SUM(D2:D17) -> 306.2 | E18: =SUM(E2:E17) -> 306.46 | F18: =SUM(F2:F17) -> 131.88589 | I18: =490/13 -> 37.692308
C19: =C18*4 -> 1116.8 | G19: =F18/F20 -> 0.22936677
C20: 900 | D20: =C20-C18-sum(C23:C27) -> 409.8 | F20: 575 | H20: =F20*75 -> 43125
C21: =C18/C20 -> 0.31022222 | E21: 150 | G21: =400/12 -> 33.333333
E22: 250
C23: 23 | E23: 33 | G23: =1800/12 -> 150
C24: 5 | E24: 800
C25: 1.5 | E25: 500
C26: 0.5 | E26: 700
C27: 181 | E27: 600
E28: 1500
E29: =SUM(E21:E28) -> 4533 | F29: =E29/25 -> 181.32

Sheet Pizza Costing New
A2: PIZZA | B2: Size | C2: Column 25 | D2: Column 24 | E2: Chicken | F2: Column 26 | G2: Column 27 | H2: Beef | I2: Pork | J2: Pepperoni | K2: Bacon | L2: Veggies | M2: Cheese | N2: Imp. Cheese | O2: Dough | P2: Sauce | Q2: Olives | R2: Mushroom | S2: Toppings | T2: Olive Oil | U2: Origano | V2: Tomato Confit | W2: BBQ SAUCE | X2: CHIMICHURRI | Y2: BUTTER | Z2: Column 4 | AA2: Column 5
A3: Wild Mushroom | B3: Small
A4: Wild Mushroom | B4: Medium
A5: Wild Mushroom | B5: Large
A6: Melanzane | B6: Small
A7: Melanzane | B7: Medium
A8: Melanzane | B8: Large
A9: Premavera | B9: Small
A10: Premavera | B10: Medium
A11: Premavera | B11: Large
A12: Grilled Paneer | B12: Small
A13: Grilled Paneer | B13: Medium
A14: Grilled Paneer | B14: Large
A15: Margherita | B15: Small | E15: 0
A16: Margherita | B16: Medium
A17: Margherita | B17: Large
A18: Quattro Formaggi | B18: Small
A19: Quattro Formaggi | B19: Medium
A20: Quattro Formaggi | B20: Large
A21: Italian Salsiccia | B21: Small
A22: Italian Salsiccia | B22: Medium
A23: Italian Salsiccia | B23: Large
A24: Capricciosa | B24: Small
A25: Capricciosa | B25: Medium
A26: Capricciosa | B26: Large
A27: Pepperoni | B27: Small
... A65: Meat Lovers Pizza | B65: Large
R82: =190/8 -> 23.75
A84: Item | C84: S | D84: Sprite | E84: GB | F84: 399 | G84: 449 | H84: 499 | I84: 549 | J84: 599 | K84: 649 | L84: 699 | M84: 749 | N84: 499 | O84: 849 | P84: 699 | Q84: 749 | R84: 499 | S84: 849 | T84: Pizza | U84: Sprite | V84: GB | W84: Pizza | X84: Sprite | Y84: GB | Z84: Pizza | AA84: Sprite | AB84: GB
A85: Wild Mushroom | C85: 450 | F85: FALSE | G85: FALSE | H85: FALSE | I85: FALSE | J85: FALSE | K85: FALSE | L85: FALSE | M85: FALSE | N85: FALSE | O85: FALSE | P85: FALSE | Q85: FALSE | R85: FALSE | S85: FALSE
A86: Melanzane | F86: FALSE | G86: FALSE | H86: FALSE | I86: FALSE | J86: FALSE | K86: FALSE | L86: FALSE | M86: FALSE | N86: FALSE | O86: FALSE | P86: FALSE | Q86: FALSE | R86: FALSE | S86: FALSE
A87: Premavera | B87: =sum(C87:E87) -> 660 | C87: 450 | D87: 20 | E87: 190 | F87: FALSE | G87: FALSE | H87: TRUE | I87: FALSE | J87: FALSE | K87: FALSE | L87: TRUE | M87: FALSE | N87: FALSE | O87: FALSE | P87: TRUE | Q87: FALSE | R87: FALSE | S87: FALSE | T87: 200 | U87: 12 | V87: 15 | W87: 270 | X87: 24 | Y87: 15 | Z87: 350 | AB87: 15
